Workbook

Sheet BRASIL
B2: Area total | C2: Area Mha | D2: %
A3: AMAZONIA | B3: 4.207828e+08 | C3: =B3/1000000 -> 420.7828 | D3: =C3/C$9 -> 0.49466326
A4: CAATINGA | B4: 86261104 | C4: =B4/1000000 -> 86.261104 | D4: =C4/C$9 -> 0.10140671
A5: CERRADO | B5: 2.0043907e+08 | C5: =B5/1000000 -> 200.43907 | D5: =C5/C$9 -> 0.23563188
A6: MATA ATLANTICA | B6: 1.0867449e+08 | C6: =B6/1000000 -> 108.67449 | D6: =C6/C$9 -> 0.12775541
A7: PAMPA | B7: 19393516 | C7: =B7/1000000 -> 19.393516 | D7: =C7/C$9 -> 0.022798603
A8: PANTANAL | B8: 15093960 | C8: =B8/1000000 -> 15.09396 | D8: =C8/C$9 -> 0.017744137
A9: Total | B9: =SUM(B3:B8) -> 850644940 | C9: =B9/1000000 -> 850.64494
B12: Area total | C12: Area Mha | D12: %
A13: Floresta | B13: 5.0574396e+08 | C13: =B13/1000000 -> 505.74396 | D13: =C13/C$9 -> 0.59454179
A14: Formação Natural não Florestal | B14: 45916553 | C14: =B14/1000000 -> 45.916553 | D14: =C14/C$9 -> 0.053978518
A15: Agropecuária | B15: 2.7331458e+08 | C15: =B15/1000000 -> 273.31459 | D15: =C15/C$9 -> 0.32130278
A16: Área não Vegetada | B16: 6374980.1 | C16: =B16/1000000 -> 6.3749801 | D16: =C16/C$9 -> 0.0074942903
A17: Corpo D'água | B17: 19293615 | C17: =B17/1000000 -> 19.293615 | D17: =C17/C$9 -> 0.022681161
A18: Não Observado | B18: 1242.4169 | C18: =B18/1000000 -> 0.0012424169 | D18: =C18/C$9 -> 1.4605587e-06
A19: Total | B19: =SUM(B13:B18) -> 850644940 | C19: =B19/1000000 -> 850.64494

Sheet DADOS COBERTURA AMAZÔNIA
A2: Para o Grafico Circular da composição do uso da terra
C4: Area total (ha) | D4: Mha
B5: 1. Forest | C5: 3.2797655e+08 | D5: =C5/1000000 -> 327.97655 | E5: =C5/$C$36 -> 0.7794438
B6: 1.1. Forest Formation | C6: 2.8627037e+08 | D6: =C6/1000000 -> 286.27037 | E6: =C6/$C$36 -> 0.6803281 | G6: 1. Floresta | H6: =C5 -> 3.2797655e+08 | I6: =H6/1000000 -> 327.97655 | J6: =E5 -> 0.7794438 | K6: =B6 -> 1.1. Forest Formation | L6: =C6 -> 2.8627037e+08 | M6: =L6/1000000 -> 286.27037 | N6: =M6/I$6 -> 0.87283792
B7: 1.2. Savanna Formation | C7: 3155783.4 | D7: =C7/1000000 -> 3.1557834 | E7: =C7/$C$36 -> 0.0074997917 | K7: =B7 -> 1.2. Savanna Formation | L7: =C7 -> 3155783.4 | M7: =L7/1000000 -> 3.1557834 | N7: =M7/I$6 -> 0.0096219789
B8: 1.3. Flooded Savanna | C8: 0 | D8: =C8/1000000 -> 0 | E8: =C8/$C$36 -> 0 | K8: =B9 -> 1.4. Mangrove | L8: =C9 -> 746837.34 | M8: =L8/1000000 -> 0.74683734 | N8: =M8/I$6 -> 0.0022771059
B9: 1.4. Mangrove | C9: 746837.34 | D9: =C9/1000000 -> 0.74683734 | E9: =C9/$C$36 -> 0.0017748761 | K9: =B10 -> 1.5. Floodable Forest | L9: =C10 -> 37803558 | M9: =L9/1000000 -> 37.803558 | N9: =M9/I$6 -> 0.11526299
B10: 1.5. Floodable Forest | C10: 37803558 | D10: =C10/1000000 -> 37.803558 | E10: =C10/$C$36 -> 0.089841025
B11: 1.6. Wooded Sandbank Vegetation | C11: 0 | D11: =C11/1000000 -> 0 | E11: =C11/$C$36 -> 0 | G11: 2. Formação Natural não Florestal | H11: =C12 -> 14763212 | I11: =H11/1000000 -> 14.763212 | J11: =E12 -> 0.035085112 | K11: =B13 -> 2.1. Wetland | L11: =C13 -> 9010925.5 | M11: =L11/1000000 -> 9.0109255 | N11: =M11/I$11 -> 0.6103635
B12: 2. Herbaceous and Shrubby Vegetation | C12: 14763212 | D12: =C12/1000000 -> 14.763212 | E12: =C12/$C$36 -> 0.035085112 | K12: =B15 -> 2.3. Grassland Formation | L12: =C15 -> 5145418.2 | M12: =L12/1000000 -> 5.1454182 | N12: =M12/I$11 -> 0.34852973
B13: 2.1. Wetland | C13: 9010925.5 | D13: =C13/1000000 -> 9.0109255 | E13: =C13/$C$36 -> 0.021414671 | K13: =B18 -> 2.6. Rocky Outcrop | L13: =C18 -> 582703.15 | M13: =L13/1000000 -> 0.58270315 | N13: =M13/I$11 -> 0.039469945
B14: 2.2. Marisma | C14: 0 | D14: =C14/1000000 -> 0 | E14: =C14/$C$36 -> 0 | K14: Outros | L14: =SUM(C14,C16,C17,C19,) -> 24164.808 | M14: =L14/1000000 -> 0.024164808 | N14: =M14/I$11 -> 0.0016368259
B15: 2.3. Grassland Formation | C15: 5145418.2 | D15: =C15/1000000 -> 5.1454182 | E15: =C15/$C$36 -> 0.012228205
B16: 2.4. Herbaceous-Shrub Mosaic | C16: 0 | D16: =C16/1000000 -> 0 | E16: =C16/$C$36 -> 0 | G16: 3. Agropecuária | H16: =C20 -> 65265981 | I16: =H16/1000000 -> 65.265981 | J16: =E20 -> 0.1551061 | K16: =B21 -> 3.1. Pasture | L16: =C21 -> 50828180 | M16: =L16/1000000 -> 50.82818 | N16: =M16/I$16 -> 0.7787852
B17: 2.5. Hypersaline Tidal Flat | C17: 24163.379 | D17: =C17/1000000 -> 0.024163379 | E17: =C17/$C$36 -> 5.7424826e-05 | K17: =B22 -> 3.2. Agriculture | L17: =C22 -> 8647890.6 | M17: =L17/1000000 -> 8.6478906 | N17: =M17/I$16 -> 0.13250227
B18: 2.6. Rocky Outcrop | C18: 582703.15 | D18: =C18/1000000 -> 0.58270315 | E18: =C18/$C$36 -> 0.0013848074 | K18: =B23 -> 3.3. Forest Plantation | L18: =C23 -> 334775.44 | M18: =L18/1000000 -> 0.33477544 | N18: =M18/I$16 -> 0.0051294018
B19: 2.7. Herbaceous Sandbank Vegetation | C19: 1.4286453 | D19: =C19/1000000 -> 1.4286453e-06 | E19: =C19/$C$36 -> 3.3952083e-09 | K19: =B24 -> 3.4. Mosaic of Uses | L19: =C24 -> 5455135 | M19: =L19/1000000 -> 5.455135 | N19: =M19/I$16 -> 0.083583131
B20: 3. Farming | C20: 65265981 | D20: =C20/1000000 -> 65.265981 | E20: =C20/$C$36 -> 0.1551061
B21: 3.1. Pasture | C21: 50828180 | D21: =C21/1000000 -> 50.82818 | E21: =C21/$C$36 -> 0.12079434 | G21: 4. Área não Vegetada | H21: =C25 -> 1193448.8 | I21: =H21/1000000 -> 1.1934488 | J21: =E25 -> 0.0028362584 | K21: =B26 -> 4.1. Beach, Dune and Sand Spot | L21: =C26 -> 7303.7485 | M21: =L21/1000000 -> 0.0073037485 | N21: =M21/$I$21 -> 0.0061198676
B22: 3.2. Agriculture | C22: 8647890.6 | D22: =C22/1000000 -> 8.6478906 | E22: =C22/$C$36 -> 0.020551911 | K22: =B27 -> 4.2. Urban Area | L22: =C27 -> 477117.94 | M22: =L22/1000000 -> 0.47711794 | N22: =M22/$I$21 -> 0.39978083
B23: 3.3. Forest Plantation | C23: 334775.44 | D23: =C23/1000000 -> 0.33477544 | E23: =C23/$C$36 -> 0.00079560153 | K23: =B28 -> 4.3. Mining | L23: =C28 -> 440793.34 | M23: =L23/1000000 -> 0.44079334 | N23: =M23/$I$21 -> 0.36934416
B24: 3.4. Mosaic of Uses | C24: 5455135 | D24: =C24/1000000 -> 5.455135 | E24: =C24/$C$36 -> 0.012964254 | K24: =B29 -> 4.4. Photovoltaic Power Plant (beta) | L24: =C29 -> 30.67071 | M24: =L24/1000000 -> 3.067071e-05 | N24: =M24/$I$21 -> 2.5699226e-05
B25: 4. Non vegetated area | C25: 1193448.8 | D25: =C25/1000000 -> 1.1934488 | E25: =C25/$C$36 -> 0.0028362584 | K25: =B30 -> 4.5. Wind Farm | L25: =C30 -> 0 | M25: =L25/1000000 -> 0 | N25: =M25/$I$21 -> 0
B26: 4.1. Beach, Dune and Sand Spot | C26: 7303.7485 | D26: =C26/1000000 -> 0.0073037485 | E26: =C26/$C$36 -> 1.7357526e-05 | K26: =B31 -> 4.6. Other non Vegetated Areas | L26: =C31 -> 268203.08 | M26: =L26/1000000 -> 0.26820308 | N26: =M26/$I$21 -> 0.22472945
B27: 4.2. Urban Area | C27: 477117.94 | D27: =C27/1000000 -> 0.47711794 | E27: =C27/$C$36 -> 0.0011338817
B28: 4.3. Mining | C28: 440793.34 | D28: =C28/1000000 -> 0.44079334 | E28: =C28/$C$36 -> 0.0010475555 | G28: 5. Corpo D'água | H28: =C32 -> 11583203 | I28: =H28/1000000 -> 11.583203 | J28: =E32 -> 0.027527747
B29: 4.4. Photovoltaic Power Plant (beta) | C29: 30.67071 | D29: =C29/1000000 -> 3.067071e-05 | E29: =C29/$C$36 -> 7.2889646e-08
B30: 4.5. Wind Farm | C30: 0 | D30: =C30/1000000 -> 0 | E30: =C30/$C$36 -> 0
B31: 4.6. Other non Vegetated Areas | C31: 268203.08 | D31: =C31/1000000 -> 0.26820308 | E31: =C31/$C$36 -> 0.00063739079
B32: 5. Water | C32: 11583203 | D32: =C32/1000000 -> 11.583203 | E32: =C32/$C$36 -> 0.027527747
B33: 5.1. River, Lake and Ocean | C33: 11572420 | D33: =C33/1000000 -> 11.57242 | E33: =C33/$C$36 -> 0.027502121
B34: 5.2. Aquaculture | C34: 10783.232 | D34: =C34/1000000 -> 0.010783232 | E34: =C34/$C$36 -> 2.5626598e-05
B35: 6. Not Observed | C35: 414.35304 | D35: =C35/1000000 -> 0.00041435304 | E35: =C35/$C$36 -> 9.8471951e-07
B36: Total Geral | C36: =SUM(C5,C12,C20,C25,C32,C35) -> 4.207828e+08 | D36: =C36/1000000 -> 420.7828

Sheet SANKEY
B2: Transições 1985 a 2025
B6: Classes | C6: 1. Forest | D6: 2. Herbaceous and Shrubby Vegetation | E6: 3. Farming | F6: 4. Non vegetated area | G6: 5. Water | H6: Total 1985
B7: 1. Forest | C7: 3.2584405e+08 | D7: 57779.661 | E7: 53478063 | F7: 671324.61 | G7: 1201712.2 | H7: =SUM(C7:G7) -> 3.8125293e+08
B8: 2. Herbaceous and Shrubby Vegetation | C8: 61771.878 | D8: 13866797 | E8: 1181687.5 | F8: 54804.833 | G8: 1039174.9 | H8: =SUM(C8:G8) -> 16204236
B9: 3. Farming | C9: 1435675.5 | D9: 100329.65 | E9: 10437191 | F9: 81748.256 | G9: 34169.126 | H9: =SUM(C9:G9) -> 12089114
B10: 4. Non vegetated area | C10: 13633.155 | D10: 5259.8186 | E10: 125925.93 | F10: 362636.48 | G10: 4969.7065 | H10: =SUM(C10:G10) -> 512425.09
B11: 5. Water | C11: 621350.24 | D11: 733004.13 | E11: 42469.243 | F11: 22933.032 | G11: 9303170.9 | H11: =SUM(C11:G11) -> 10722928
B12: Total 2025 | C12: =SUM(C7:C11) -> 3.2797649e+08 | D12: =SUM(D7:D11) -> 14763170 | E12: =SUM(E7:E11) -> 65265336 | F12: =SUM(F7:F11) -> 1193447.2 | G12: =SUM(G7:G11) -> 11583197 | H12: =SUM(H7:H11) -> 420781636
C15: Vegetação Nativa | D15: Agropecuária | E15: Outros | F15: Total
B16: Vegetação Nativa | C16: =SUM(C7:D8) -> 3.398304e+08 | D16: =SUM(E7:E8) -> 54659750 | E16: =SUM(F7:G8) -> 2967016.5 | F16: =SUM(C16:E16) -> 3.9745717e+08
B17: Agropecuária | C17: =C9+D9 -> 1536005.2 | D17: =E9 -> 10437191 | E17: =SUM(F9:G9) -> 115917.38 | F17: =SUM(C17:E17) -> 12089114
B18: Outros | C18: =SUM(C10:D11) -> 1373247.3 | D18: =E10+E11 -> 168395.17 | E18: =SUM(F10:G11) -> 9693710.1 | F18: =SUM(C18:E18) -> 11235353
B19: Total | C19: =SUM(C16:C18) -> 3.4273966e+08 | D19: =SUM(D16:D18) -> 65265336 | E19: =SUM(E16:E18) -> 12776644 | F19: =SUM(C16:E18) -> 420781636

Sheet GRAFICO HISTORICO
A2: AMAZÔNIA
B4: 1985 | C4: 1986 | D4: 1987 | E4: 1988 | F4: 1989 | G4: 1990 | H4: 1991 | I4: 1992 | J4: 1993 | K4: 1994 | L4: 1995 | M4: 1996 | N4: 1997 | O4: 1998 | P4: 1999 | Q4: 2000 | R4: 2001 | S4: 2002 | T4: 2003 | U4: 2004 | V4: 2005 | W4: 2006 | X4: 2007 | Y4: 2008 | Z4: 2009 | AA4: 2010 | AB4: 2011 | AC4: 2012 | AD4: 2013 | AE4: 2014 | AF4: 2015 | AG4: 2016 | AH4: 2017 | AI4: 2018 | AJ4: 2019 | AK4: 2020 | AL4: 2021 | AM4: 2022 | AN4: 2023 | AO4: 2024 | AP4: 2025
A5: 1. Forest | B5: 3.8125295e+08 | C5: 3.8083498e+08 | D5: 3.793106e+08 | E5: 3.779092e+08 | F5: 3.7670774e+08 | G5: 3.7582679e+08 | H5: 3.7465856e+08 | I5: 3.7303941e+08 | J5: 3.7148072e+08 | K5: 3.6969755e+08 | L5: 3.673447e+08 | M5: 3.6527328e+08 | N5: 3.63335e+08 | O5: 3.6135201e+08 | P5: 3.5923191e+08 | Q5: 3.5791779e+08 | R5: 3.5612773e+08 | S5: 3.5408774e+08 | T5: 3.5129484e+08 | U5: 3.4874289e+08 | V5: 3.4675595e+08 | W5: 3.4521047e+08 | X5: 3.4402067e+08 | Y5: 3.4279097e+08 | Z5: 3.420321e+08 | AA5: 3.4162121e+08 | AB5: 3.4117285e+08 | AC5: 3.4075275e+08 | AD5: 3.4019114e+08 | AE5: 3.395853e+08 | AF5: 3.3879043e+08 | AG5: 3.3793626e+08 | AH5: 3.3723793e+08 | AI5: 3.3656925e+08 | AJ5: 3.3533361e+08 | AK5: 3.341803e+08 | AL5: 3.326674e+08 | AM5: 3.3095866e+08 | AN5: 3.2948913e+08 | AO5: 3.2864053e+08 | AP5: 3.2797655e+08 | AR5: =AP5-B5 -> -53276409 | AS5: =AR5/B5 -> -0.13974032 | AT5: % de cobertura florestal | AU5: =AP5/AP36 -> 0.7794438
A6: 1.1. Forest Formation | B6: 3.3597547e+08 | C6: 3.3581219e+08 | D6: 3.3450916e+08 | E6: 3.3333417e+08 | F6: 3.3241542e+08 | G6: 3.316107e+08 | H6: 3.3057046e+08 | I6: 3.2908725e+08 | J6: 3.2770201e+08 | K6: 3.2605119e+08 | L6: 3.2389367e+08 | M6: 3.2205054e+08 | N6: 3.202794e+08 | O6: 3.1851091e+08 | P6: 3.1667704e+08 | Q6: 3.1517051e+08 | R6: 3.1340623e+08 | S6: 3.1142861e+08 | T6: 3.0869859e+08 | U6: 3.0622039e+08 | V6: 3.0426188e+08 | W6: 3.0276268e+08 | X6: 3.0159753e+08 | Y6: 3.0042526e+08 | Z6: 2.9973243e+08 | AA6: 2.9931364e+08 | AB6: 2.988505e+08 | AC6: 2.984535e+08 | AD6: 2.9788079e+08 | AE6: 2.9729499e+08 | AF6: 2.9651916e+08 | AG6: 2.9570401e+08 | AH6: 2.9505149e+08 | AI6: 2.9439428e+08 | AJ6: 2.9319691e+08 | AK6: 2.9204129e+08 | AL6: 2.9058833e+08 | AM6: 2.8900709e+08 | AN6: 2.8763422e+08 | AO6: 2.8680266e+08 | AP6: 2.8627037e+08 | AR6: =AP6-B6 -> -49705103 | AS6: =AR6/B6 -> -0.14794266 | AT6: % de cobertura por vegetação nativa | AU6: =(AP5+AP12)/AP36 -> 0.81452891
A7: 1.2. Savanna Formation | B7: 3955401.8 | C7: 3903841.6 | D7: 3845174.9 | E7: 3800089.6 | F7: 3776248.2 | G7: 3758226.7 | H7: 3728867.6 | I7: 3696976.1 | J7: 3664272.1 | K7: 3630027.3 | L7: 3580311.7 | M7: 3541815.1 | N7: 3492213.9 | O7: 3430106.9 | P7: 3374573.2 | Q7: 3355945.6 | R7: 3345003.9 | S7: 3329433 | T7: 3305695.1 | U7: 3286304 | V7: 3275827.5 | W7: 3264450.9 | X7: 3257469.2 | Y7: 3247613 | Z7: 3242485.9 | AA7: 3237937.2 | AB7: 3236520.7 | AC7: 3238254.1 | AD7: 3238426.1 | AE7: 3236784.9 | AF7: 3233167.8 | AG7: 3225059.7 | AH7: 3218917.6 | AI7: 3213282.2 | AJ7: 3209376.2 | AK7: 3208393 | AL7: 3197005.6 | AM7: 3186023.3 | AN7: 3185057.7 | AO7: 3166186.4 | AP7: 3155783.4 | AR7: =AP7-B7 -> -799618.41 | AS7: =AR7/B7 -> -0.20215858 | AT7: Perda de floresta entre 1985 e 2025 | AU7: =AR5 -> -53276409
A8: 1.3. Flooded Savanna | B8: 0.085822748 | C8: 0.085822748 | D8: 0 | E8: 0.085822748 | F8: 0 | G8: 0 | H8: 0.085822748 | I8: 0 | J8: 0 | K8: 0 | L8: 0 | M8: 0 | N8: 0 | O8: 0 | P8: 0.086166382 | Q8: 0 | R8: 0 | S8: 0 | T8: 0 | U8: 0 | V8: 0 | W8: 0 | X8: 0 | Y8: 0 | Z8: 0 | AA8: 0 | AB8: 0 | AC8: 0 | AD8: 0 | AE8: 0 | AF8: 0 | AG8: 0 | AH8: 0 | AI8: 0 | AJ8: 0 | AK8: 0 | AL8: 0 | AM8: 0 | AN8: 0 | AO8: 0 | AP8: 0 | AR8: =AP8-B8 -> -0.085822748 | AS8: =AR8/B8 -> -1 | AT8: Perda de vegetação nativa entre 1985 e 2025 | AU8: =AR5+AR12 -> -54717447
A9: 1.4. Mangrove | B9: 728179.21 | C9: 727565.95 | D9: 725805.82 | E9: 726279.7 | F9: 729271.44 | G9: 733173.61 | H9: 735900.22 | I9: 735868.41 | J9: 735064.59 | K9: 735723.46 | L9: 737531.54 | M9: 738590.79 | N9: 738410.06 | O9: 732239.39 | P9: 728128.45 | Q9: 732870.19 | R9: 732930.23 | S9: 733516.29 | T9: 734300.67 | U9: 734971.83 | V9: 733837.6 | W9: 732795.41 | X9: 732031.25 | Y9: 732311.38 | Z9: 733771.89 | AA9: 733360.86 | AB9: 735283.79 | AC9: 735253.72 | AD9: 734876.5 | AE9: 736148.6 | AF9: 732714.11 | AG9: 729883.47 | AH9: 729591.15 | AI9: 729918.28 | AJ9: 733129.77 | AK9: 730320.97 | AL9: 735515.31 | AM9: 737442.57 | AN9: 744129.92 | AO9: 746697.71 | AP9: 746837.34 | AR9: =AP9-B9 -> 18658.13 | AS9: =AR9/B9 -> 0.025622992
A10: 1.5. Floodable Forest | B10: 40593903 | C10: 40391379 | D10: 40230468 | E10: 40048660 | F10: 39786800 | G10: 39724691 | H10: 39623338 | I10: 39519318 | J10: 39379367 | K10: 39280609 | L10: 39133183 | M10: 38942336 | N10: 38824976 | O10: 38678751 | P10: 38452170 | Q10: 38658459 | R10: 38643566 | S10: 38596179 | T10: 38556249 | U10: 38501226 | V10: 38484408 | W10: 38450547 | X10: 38433634 | Y10: 38385786 | Z10: 38323412 | AA10: 38336265 | AB10: 38350544 | AC10: 38325748 | AD10: 38337039 | AE10: 38317374 | AF10: 38305389 | AG10: 38277301 | AH10: 38237939 | AI10: 38231765 | AJ10: 38194194 | AK10: 38200295 | AL10: 38146553 | AM10: 38028103 | AN10: 37925717 | AO10: 37924988 | AP10: 37803558 | AR10: =AP10-B10 -> -2790345 | AS10: =AR10/B10 -> -0.068738032 | AT10: Expansão da agropécuária entre 1985 e 2025 | AU10: =AR20/B20 -> 4.3987349
A11: 1.6. Wooded Sandbank Vegetation | B11: 0 | C11: 0 | D11: 0 | E11: 0 | F11: 0 | G11: 0 | H11: 0 | I11: 0 | J11: 0 | K11: 0 | L11: 0 | M11: 0 | N11: 0 | O11: 0 | P11: 0 | Q11: 0 | R11: 0 | S11: 0 | T11: 0 | U11: 0 | V11: 0 | W11: 0 | X11: 0 | Y11: 0 | Z11: 0 | AA11: 0 | AB11: 0 | AC11: 0 | AD11: 0 | AE11: 0 | AF11: 0 | AG11: 0 | AH11: 0 | AI11: 0 | AJ11: 0 | AK11: 0 | AL11: 0 | AM11: 0 | AN11: 0 | AO11: 0 | AP11: 0 | AR11: =AP11-B11 -> 0 | AS11: - | AT11: % das florestas naturais do Brasil na Amazônia | AU11: =AP5/BRASIL!B13 -> 0.64850313
A12: 2. Herbaceous and Shrubby Vegetation | B12: 16204250 | C12: 15726366 | D12: 15625948 | E12: 15577183 | F12: 15438568 | G12: 15406454 | H12: 15255607 | I12: 15325188 | J12: 15079323 | K12: 15186683 | L12: 15288442 | M12: 14951075 | N12: 15093164 | O12: 15235257 | P12: 14783008 | Q12: 15587714 | R12: 15708597 | S12: 15626673 | T12: 15778897 | U12: 15760054 | V12: 15514292 | W12: 15380218 | X12: 15303604 | Y12: 15282282 | Z12: 15203920 | AA12: 15411029 | AB12: 15364010 | AC12: 15205268 | AD12: 15424574 | AE12: 15482765 | AF12: 15579620 | AG12: 15693970 | AH12: 15560555 | AI12: 15580278 | AJ12: 15485438 | AK12: 15511655 | AL12: 15305063 | AM12: 14651798 | AN12: 15186644 | AO12: 15339115 | AP12: 14763212 | AR12: =AP12-B12 -> -1441038.5 | AS12: =AR12/B12 -> -0.088929662
A13: 2.1. Wetland | B13: 9816075.2 | C13: 9363654.2 | D13: 9280783.4 | E13: 9239421.4 | F13: 9117012.7 | G13: 9089854.9 | H13: 8959708.3 | I13: 9037134.9 | J13: 8794114.2 | K13: 8910836.3 | L13: 9019414.1 | M13: 8698474 | N13: 8851449.3 | O13: 9007354.7 | P13: 8568825.3 | Q13: 9379172.6 | R13: 9515865 | S13: 9453349.3 | T13: 9619443.8 | U13: 9616473.4 | V13: 9394546 | W13: 9287406.4 | X13: 9222361.5 | Y13: 9214156.1 | Z13: 9139955.6 | AA13: 9353775 | AB13: 9311778.8 | AC13: 9158565 | AD13: 9396329.3 | AE13: 9484404.4 | AF13: 9600281.8 | AG13: 9730048.9 | AH13: 9611762.1 | AI13: 9645681.8 | AJ13: 9568864.6 | AK13: 9613951.5 | AL13: 9415082.1 | AM13: 8792351.2 | AN13: 9363170.4 | AO13: 9548290.7 | AP13: 9010925.5 | AR13: =AP13-B13 -> -805149.69 | AS13: =AR13/B13 -> -0.082023587
A14: 2.2. Marisma | B14: 0 | C14: 0 | D14: 0 | E14: 0 | F14: 0 | G14: 0 | H14: 0 | I14: 0 | J14: 0 | K14: 0 | L14: 0 | M14: 0 | N14: 0 | O14: 0 | P14: 0 | Q14: 0 | R14: 0 | S14: 0 | T14: 0 | U14: 0 | V14: 0 | W14: 0 | X14: 0 | Y14: 0 | Z14: 0 | AA14: 0 | AB14: 0 | AC14: 0 | AD14: 0 | AE14: 0 | AF14: 0 | AG14: 0 | AH14: 0 | AI14: 0 | AJ14: 0 | AK14: 0 | AL14: 0 | AM14: 0 | AN14: 0 | AO14: 0 | AP14: 0 | AR14: =AP14-B14 -> 0 | AS14: -
A15: 2.3. Grassland Formation | B15: 5765241.8 | C15: 5739795.2 | D15: 5722200.1 | E15: 5715281.2 | F15: 5701309 | G15: 5696660.1 | H15: 5674909.2 | I15: 5666633.6 | J15: 5662715 | K15: 5653328.7 | L15: 5647000.2 | M15: 5631536.1 | N15: 5620350.5 | O15: 5605401.2 | P15: 5591469.6 | Q15: 5585000.5 | R15: 5568591 | S15: 5549041.5 | T15: 5535162.4 | U15: 5519687.3 | V15: 5495761.6 | W15: 5468659.1 | X15: 5457600.2 | Y15: 5445565 | Z15: 5441510.3 | AA15: 5434762.6 | AB15: 5430862.1 | AC15: 5426837.4 | AD15: 5409231.6 | AE15: 5379696.9 | AF15: 5360663.8 | AG15: 5345331.1 | AH15: 5331147.4 | AI15: 5318137 | AJ15: 5301832.3 | AK15: 5283520.1 | AL15: 5275937.2 | AM15: 5246042 | AN15: 5210789.7 | AO15: 5179773.1 | AP15: 5145418.2 | AR15: =AP15-B15 -> -619823.57 | AS15: =AR15/B15 -> -0.10751042
A16: 2.4. Herbaceous-Shrub Mosaic | B16: 0 | C16: 0 | D16: 0 | E16: 0 | F16: 0 | G16: 0 | H16: 0 | I16: 0 | J16: 0 | K16: 0 | L16: 0 | M16: 0 | N16: 0 | O16: 0 | P16: 0 | Q16: 0 | R16: 0 | S16: 0 | T16: 0 | U16: 0 | V16: 0 | W16: 0 | X16: 0 | Y16: 0 | Z16: 0 | AA16: 0 | AB16: 0 | AC16: 0 | AD16: 0 | AE16: 0 | AF16: 0 | AG16: 0 | AH16: 0 | AI16: 0 | AJ16: 0 | AK16: 0 | AL16: 0 | AM16: 0 | AN16: 0 | AO16: 0 | AP16: 0 | AR16: =AP16-B16 -> 0 | AS16: -
A17: 2.5. Hypersaline Tidal Flat | B17: 36898.888 | C17: 36923.175 | D17: 36929.164 | E17: 36652.504 | F17: 34300.844 | G17: 33885.243 | H17: 34678.469 | I17: 35094.304 | J17: 36284.688 | K17: 36626.79 | L17: 36317.438 | M17: 35506.47 | N17: 35598.514 | O17: 36220.72 | P17: 36092.02 | Q17: 36961.243 | R17: 37623.165 | S17: 37712.8 | T17: 37736.559 | U17: 37260.61 | V17: 37351.481 | W17: 37546.727 | X17: 36996.891 | Y17: 35874.772 | Z17: 35731.218 | AA17: 35759.426 | AB17: 34663.511 | AC17: 33140.474 | AD17: 32280.977 | AE17: 31863.894 | AF17: 31871.11 | AG17: 31754.781 | AH17: 30867.911 | AI17: 29668.982 | AJ17: 27964.999 | AK17: 27335.694 | AL17: 27222.985 | AM17: 26918.703 | AN17: 26407.01 | AO17: 25365.597 | AP17: 24163.379 | AR17: =AP17-B17 -> -12735.509 | AS17: =AR17/B17 -> -0.34514615
A18: 2.6. Rocky Outcrop | B18: 586033.14 | C18: 585991.86 | D18: 586033.8 | E18: 585826.41 | F18: 585944.25 | G18: 586051.78 | H18: 586309.7 | I18: 586323.86 | J18: 586207.77 | K18: 585890.38 | L18: 585709.08 | M18: 585558.21 | N18: 585765.31 | O18: 586279.42 | P18: 586620.16 | Q18: 586578.45 | R18: 586516.15 | S18: 586567.56 | T18: 586551.7 | U18: 586631.2 | V18: 586630.61 | W18: 586603.52 | X18: 586643.44 | Y18: 586683.61 | Z18: 586720.85 | AA18: 586729.83 | AB18: 586703.84 | AC18: 586722.77 | AD18: 586729.64 | AE18: 586796.66 | AF18: 586799.97 | AG18: 586831.23 | AH18: 586774.55 | AI18: 586787.86 | AJ18: 586773.47 | AK18: 586845.49 | AL18: 586818.68 | AM18: 586484.44 | AN18: 586275.96 | AO18: 585684.37 | AP18: 582703.15 | AR18: =AP18-B18 -> -3329.988 | AS18: =AR18/B18 -> -0.005682252
A19: 2.7. Herbaceous Sandbank Vegetation | B19: 1.1608301 | C19: 1.2501242 | D19: 1.2501145 | E19: 1.607323 | F19: 1.6073209 | G19: 1.518031 | H19: 1.0715367 | I19: 1.8752526 | J19: 1.0714566 | K19: 1.1607375 | L19: 0.71431309 | M19: 0.53576107 | N19: 0.71435575 | O19: 1.0714983 | P19: 1.3393765 | Q19: 1.5179863 | R19: 1.8751339 | S19: 2.1430833 | T19: 2.0537561 | U19: 1.785864 | V19: 2.0537492 | W19: 2.1430502 | X19: 2.4109412 | Y19: 2.3215854 | Z19: 2.1430581 | AA19: 2.053754 | AB19: 2.143039 | AC19: 2.6787366 | AD19: 2.6787372 | AE19: 2.6787815 | AF19: 3.2146013 | AG19: 3.5717651 | AH19: 2.768101 | AI19: 2.7680868 | AJ19: 2.9467067 | AK19: 1.9644431 | AL19: 1.8752198 | AM19: 1.5179927 | AN19: 1.2501094 | AO19: 1.6072335 | AP19: 1.4286453 | AR19: =AP19-B19 -> 0.26781516 | AS19: =AR19/B19 -> 0.23071004
A20: 3. Farming | B20: 12089125 | C20: 12326133 | D20: 13766185 | E20: 15057455 | F20: 16073290 | G20: 16973346 | H20: 18082020 | I20: 19727703 | J20: 21277040 | K20: 23097365 | L20: 25466790 | M20: 27515351 | N20: 29521198 | O20: 31526345 | P20: 33558287 | Q20: 35197439 | R20: 37062164 | S20: 39099717 | T20: 41893323 | U20: 44456201 | V20: 46454490 | W20: 48015631 | X20: 49202000 | Y20: 50443483 | Z20: 51195690 | AA20: 51676509 | AB20: 52172605 | AC20: 52535148 | AD20: 53134862 | AE20: 53748717 | AF20: 54564022 | AG20: 55419932 | AH20: 56073992 | AI20: 56736008 | AJ20: 57941250 | AK20: 59090603 | AL20: 60543172 | AM20: 62248000 | AN20: 63802971 | AO20: 64700860 | AP20: 65265981 | AR20: =AP20-B20 -> 53176856 | AS20: =AR20/B20 -> 4.3987349
A21: 3.1. Pasture | B21: 7746736.9 | C21: 9277356.7 | D21: 10954237 | E21: 12348696 | F21: 13466839 | G21: 14455453 | H21: 15545527 | I21: 17004180 | J21: 18371714 | K21: 20057126 | L21: 22180522 | M21: 24098629 | N21: 25866768 | O21: 27794638 | P21: 29660431 | Q21: 31332928 | R21: 32929532 | S21: 34705402 | T21: 37170699 | U21: 39226949 | V21: 41003127 | W21: 42268960 | X21: 43437438 | Y21: 44451815 | Z21: 45041858 | AA21: 45404555 | AB21: 45755329 | AC21: 45899949 | AD21: 45858235 | AE21: 45849287 | AF21: 46030122 | AG21: 46340159 | AH21: 46551274 | AI21: 46930779 | AJ21: 47446734 | AK21: 48018870 | AL21: 48670781 | AM21: 49365687 | AN21: 50432683 | AO21: 50891786 | AP21: 50828180 | AR21: =AP21-B21 -> 43081443 | AS21: =AR21/B21 -> 5.5612373
A22: 3.2. Agriculture | B22: 161055.28 | C22: 151011.99 | D22: 177019.79 | E22: 204969.86 | F22: 228951.04 | G22: 253307.03 | H22: 277092.35 | I22: 301021.05 | J22: 337955.03 | K22: 391035.62 | L22: 437993.53 | M22: 521866.43 | N22: 581813.61 | O22: 671689.81 | P22: 755727.01 | Q22: 885547.84 | R22: 1094314.3 | S22: 1283044.9 | T22: 1801457.6 | U22: 2190263.4 | V22: 2594392.5 | W22: 2915668.1 | X22: 3086693 | Y22: 3273944.3 | Z22: 3408170.2 | AA22: 3581748 | AB22: 3688419.1 | AC22: 3962810.3 | AD22: 4609732.3 | AE22: 5194358.2 | AF22: 5755740.9 | AG22: 6180716.6 | AH22: 6645567.1 | AI22: 6872800.6 | AJ22: 7154366.4 | AK22: 7419389.3 | AL22: 7580412.9 | AM22: 7805967 | AN22: 8108558.5 | AO22: 8319332.8 | AP22: 8647890.6 | AR22: =AP22-B22 -> 8486835.3 | AS22: =AR22/B22 -> 52.695168
A23: 3.3. Forest Plantation | B23: 2330.657 | C23: 2369.533 | D23: 19153.782 | E23: 20068.824 | F23: 25699.184 | G23: 37197.221 | H23: 39725.006 | I23: 44507.617 | J23: 55031.467 | K23: 74731.826 | L23: 95342.196 | M23: 112769.65 | N23: 121210.48 | O23: 129997.36 | P23: 141808.92 | Q23: 157734.41 | R23: 163035.88 | S23: 168247.77 | T23: 172602.62 | U23: 180015.92 | V23: 195040.88 | W23: 201677.72 | X23: 205066.81 | Y23: 210809.45 | Z23: 217421.78 | AA23: 225660.35 | AB23: 234589.76 | AC23: 249126.77 | AD23: 279822.19 | AE23: 289638.04 | AF23: 296697.08 | AG23: 301139.19 | AH23: 310014.1 | AI23: 314801.42 | AJ23: 326862.01 | AK23: 329131.77 | AL23: 338513.25 | AM23: 338403.35 | AN23: 337351.05 | AO23: 335605.55 | AP23: 334775.44 | AR23: =AP23-B23 -> 332444.78 | AS23: =AR23/B23 -> 142.63994
A24: 3.4. Mosaic of Uses | B24: 4179002.1 | C24: 2895395.1 | D24: 2615774.2 | E24: 2483720.8 | F24: 2351801 | G24: 2227388.9 | H24: 2219676.1 | I24: 2377993.8 | J24: 2512339.9 | K24: 2574470.9 | L24: 2752932.2 | M24: 2782085.7 | N24: 2951405.7 | O24: 2930020.2 | P24: 3000319.8 | Q24: 2821228.9 | R24: 2875282.1 | S24: 2943022.5 | T24: 2748564.1 | U24: 2858972.1 | V24: 2661929.4 | W24: 2629325.3 | X24: 2472802.4 | Y24: 2506913.9 | Z24: 2528239.4 | AA24: 2464545.4 | AB24: 2494267.8 | AC24: 2423262.1 | AD24: 2387072.9 | AE24: 2415433.7 | AF24: 2481461.9 | AG24: 2597916.4 | AH24: 2567137.3 | AI24: 2617626.1 | AJ24: 3013287.8 | AK24: 3323212.2 | AL24: 3953464.9 | AM24: 4737943.1 | AN24: 4924378.6 | AO24: 5154135.8 | AP24: 5455135 | AR24: =AP24-B24 -> 1276133 | AS24: =AR24/B24 -> 0.30536787
A25: 4. Non vegetated area | B25: 512425.09 | C25: 541074.06 | D25: 580981.17 | E25: 613608.58 | F25: 623323.11 | G25: 622524.44 | H25: 652969.57 | I25: 671964.18 | J25: 677985.29 | K25: 692452.9 | L25: 726252.86 | M25: 749717.36 | N25: 769085.68 | O25: 793138.79 | P25: 817780.7 | Q25: 831934.18 | R25: 834564.67 | S25: 856054.28 | T25: 890229.41 | U25: 905767.01 | V25: 922916.09 | W25: 929021.79 | X25: 933436.7 | Y25: 942312.5 | Z25: 939552.55 | AA25: 910733.39 | AB25: 877275.08 | AC25: 870065.78 | AD25: 883611.88 | AE25: 898082.91 | AF25: 918917.67 | AG25: 944647.34 | AH25: 959951.67 | AI25: 964115.85 | AJ25: 974962.65 | AK25: 1012990 | AL25: 1054798.4 | AM25: 1095987.3 | AN25: 1115780.4 | AO25: 1163120.8 | AP25: 1193448.8 | AR25: =AP25-B25 -> 681023.69 | AS25: =AR25/B25 -> 1.329021
A26: 4.1. Beach, Dune and Sand Spot | B26: 5408.4883 | C26: 5410.0081 | D26: 6773.2861 | E26: 6918.3196 | F26: 6947.5685 | G26: 7034.1234 | H26: 7252.6425 | I26: 7109.6519 | J26: 7548.2178 | K26: 8136.2014 | L26: 8709.7543 | M26: 8864.4107 | N26: 8892.7431 | O26: 8885.8809 | P26: 8749.3278 | Q26: 8721.4453 | R26: 8827.5234 | S26: 8645.3809 | T26: 8521.0169 | U26: 8245.2202 | V26: 8202.31 | W26: 8337.94 | X26: 8489.0893 | Y26: 8442.0858 | Z26: 8233.3046 | AA26: 8428.6583 | AB26: 8418.6211 | AC26: 8244.2419 | AD26: 7860.3314 | AE26: 7841.1118 | AF26: 7763.9504 | AG26: 7694.0089 | AH26: 7414.3352 | AI26: 7467.3824 | AJ26: 7418.3483 | AK26: 7402.0592 | AL26: 7275.7982 | AM26: 6979.9437 | AN26: 7045.4918 | AO26: 7755.5622 | AP26: 7303.7485 | AR26: =AP26-B26 -> 1895.2602 | AS26: =AR26/B26 -> 0.35042328
A27: 4.2. Urban Area | B27: 226008.74 | C27: 232164.89 | D27: 237216.49 | E27: 245117.37 | F27: 251759.82 | G27: 259106.82 | H27: 268228.92 | I27: 276684.18 | J27: 284893.77 | K27: 293724.57 | L27: 305012.93 | M27: 315111.27 | N27: 323422.96 | O27: 330625.52 | P27: 336261.97 | Q27: 341858.8 | R27: 347776.11 | S27: 353820.53 | T27: 359623.11 | U27: 364945.76 | V27: 369900.92 | W27: 374839.76 | X27: 378831 | Y27: 383659.45 | Z27: 388800.91 | AA27: 394328.15 | AB27: 400315.25 | AC27: 407099.18 | AD27: 413543.16 | AE27: 419494.04 | AF27: 425315.88 | AG27: 430370.78 | AH27: 434420.62 | AI27: 438045.77 | AJ27: 441528.5 | AK27: 445590.74 | AL27: 449206.25 | AM27: 453941.51 | AN27: 458595.35 | AO27: 468608.78 | AP27: 477117.94 | AR27: =AP27-B27 -> 251109.2 | AS27: =AR27/B27 -> 1.1110597
A28: 4.3. Mining | B28: 32716.157 | C28: 42354.556 | D28: 55321.035 | E28: 73203.742 | F28: 96631.74 | G28: 112289.27 | H28: 118980.26 | I28: 127467.89 | J28: 138881.25 | K28: 144685.34 | L28: 147890.86 | M28: 151835.74 | N28: 156875.47 | O28: 160393.52 | P28: 162220.45 | Q28: 165826.59 | R28: 168158.71 | S28: 170527.2 | T28: 173402.37 | U28: 175691.93 | V28: 178993.54 | W28: 181157.44 | X28: 183582.5 | Y28: 186096.82 | Z28: 189864 | AA28: 192311.5 | AB28: 196032.28 | AC28: 200020.79 | AD28: 204545.32 | AE28: 211699.28 | AF28: 219698.07 | AG28: 229334.72 | AH28: 240777.99 | AI28: 251283.09 | AJ28: 265154.96 | AK28: 304271.15 | AL28: 333899.81 | AM28: 362272.69 | AN28: 389372.58 | AO28: 412018.77 | AP28: 440793.34 | AR28: =AP28-B28 -> 408077.18 | AS28: =AR28/B28 -> 12.473262
A29: 4.4. Photovoltaic Power Plant (beta) | B29: 0 | C29: 0 | D29: 0 | E29: 0 | F29: 0 | G29: 0 | H29: 0 | I29: 0 | J29: 0 | K29: 0 | L29: 0 | M29: 0 | N29: 0 | O29: 0 | P29: 0 | Q29: 0 | R29: 0 | S29: 0 | T29: 0 | U29: 0 | V29: 0 | W29: 0 | X29: 0 | Y29: 0 | Z29: 0 | AA29: 0 | AB29: 0 | AC29: 0 | AD29: 0 | AE29: 0 | AF29: 0 | AG29: 0 | AH29: 0 | AI29: 0.61750423 | AJ29: 16.561835 | AK29: 20.086309 | AL29: 24.763521 | AM29: 25.998181 | AN29: 25.909769 | AO29: 26.878414 | AP29: 30.67071 | AR29: =AP29-B29 -> 30.67071 | AS29: -
A30: 4.5. Wind Farm | B30: 0 | C30: 0 | D30: 0 | E30: 0 | F30: 0 | G30: 0 | H30: 0 | I30: 0 | J30: 0 | K30: 0 | L30: 0 | M30: 0 | N30: 0 | O30: 0 | P30: 0 | Q30: 0 | R30: 0 | S30: 0 | T30: 0 | U30: 0 | V30: 0 | W30: 0 | X30: 0 | Y30: 0 | Z30: 0 | AA30: 0 | AB30: 0 | AC30: 0 | AD30: 0 | AE30: 0 | AF30: 0 | AG30: 0 | AH30: 0 | AI30: 0 | AJ30: 0 | AK30: 0 | AL30: 0 | AM30: 0 | AN30: 0 | AO30: 0 | AP30: 0 | AR30: =AP30-B30 -> 0 | AS30: -
A31: 4.6. Other non Vegetated Areas | B31: 248291.7 | C31: 261144.6 | D31: 281670.36 | E31: 288369.15 | F31: 267983.98 | G31: 244094.23 | H31: 258507.74 | I31: 260702.46 | J31: 246662.06 | K31: 245906.79 | L31: 264639.31 | M31: 273905.94 | N31: 279894.51 | O31: 293233.86 | P31: 310548.95 | Q31: 315527.34 | R31: 309802.32 | S31: 323061.18 | T31: 348682.92 | U31: 356884.1 | V31: 365819.32 | W31: 364686.65 | X31: 362534.11 | Y31: 364114.15 | Z31: 352654.34 | AA31: 315665.08 | AB31: 272508.93 | AC31: 254701.58 | AD31: 257663.08 | AE31: 259048.48 | AF31: 266139.77 | AG31: 277247.84 | AH31: 277338.72 | AI31: 267318.99 | AJ31: 260844.27 | AK31: 255705.97 | AL31: 264391.8 | AM31: 272767.13 | AN31: 260741.1 | AO31: 274710.81 | AP31: 268203.08 | AR31: =AP31-B31 -> 19911.38 | AS31: =AR31/B31 -> 0.080193499
A32: 5. Water | B32: 10722941 | C32: 11353161 | D32: 11498012 | E32: 11624319 | F32: 11938865 | G32: 11952683 | H32: 12132656 | I32: 12017581 | J32: 12266783 | K32: 12107862 | L32: 11955786 | M32: 12292559 | N32: 12063560 | O32: 11875290 | P32: 12391071 | Q32: 11247197 | R32: 11049063 | S32: 11111992 | T32: 10924931 | U32: 10917310 | V32: 11134587 | W32: 11246903 | X32: 11322545 | Y32: 11323220 | Z32: 11411031 | AA32: 11162834 | AB32: 11195574 | AC32: 11419079 | AD32: 11148121 | AE32: 11067439 | AF32: 10929315 | AG32: 10787490 | AH32: 10949876 | AI32: 10932680 | AJ32: 11047090 | AK32: 10986803 | AL32: 11211919 | AM32: 11827917 | AN32: 11187845 | AO32: 10938752 | AP32: 11583203 | AR32: =AP32-B32 -> 860261.45 | AS32: =AR32/B32 -> 0.080226258
A33: 5.1. River, Lake and Ocean | B33: 10722843 | C33: 11353073 | D33: 11497939 | E33: 11624273 | F33: 11938828 | G33: 11952630 | H33: 12132583 | I33: 12017530 | J33: 12266741 | K33: 12107810 | L33: 11955725 | M33: 12292479 | N33: 12063506 | O33: 11875226 | P33: 12390960 | Q33: 11247068 | R33: 11048906 | S33: 11111816 | T33: 10924713 | U33: 10917082 | V33: 11134321 | W33: 11246548 | X33: 11322125 | Y33: 11322628 | Z33: 11410313 | AA33: 11161709 | AB33: 11192505 | AC33: 11414162 | AD33: 11141802 | AE33: 11060051 | AF33: 10920873 | AG33: 10778409 | AH33: 10940367 | AI33: 10922672 | AJ33: 11036646 | AK33: 10976965 | AL33: 11201974 | AM33: 11817949 | AN33: 11177740 | AO33: 10928738 | AP33: 11572420 | AR33: =AP33-B33 -> 849576.26 | AS33: =AR33/B33 -> 0.079230503
A34: 5.2. Aquaculture | B34: 98.038459 | C34: 87.944258 | D34: 73.698297 | E34: 46.366576 | F34: 37.426272 | G34: 52.624663 | H34: 72.202117 | I34: 51.647226 | J34: 42.60168 | K34: 52.493084 | L34: 60.82292 | M34: 80.030785 | N34: 53.610887 | O34: 63.497466 | P34: 111.36482 | Q34: 129.42441 | R34: 156.65239 | S34: 175.77601 | T34: 217.72338 | U34: 227.99523 | V34: 265.78959 | W34: 355.18368 | X34: 419.59596 | Y34: 591.47945 | Z34: 718.26388 | AA34: 1125.3287 | AB34: 3068.4699 | AC34: 4917.1409 | AD34: 6319.5247 | AE34: 7388.0692 | AF34: 8442.3803 | AG34: 9081.1768 | AH34: 9509.2104 | AI34: 10007.882 | AJ34: 10444.261 | AK34: 9838.1944 | AL34: 9945.0537 | AM34: 9968.5314 | AN34: 10104.672 | AO34: 10014.013 | AP34: 10783.232 | AR34: =AP34-B34 -> 10685.193 | AS34: =AR34/B34 -> 108.98981
A35: 6. Not Observed | B35: 1108.0928 | C35: 1092.9757 | D35: 1073.8007 | E35: 1039.7197 | F35: 1016.6118 | G35: 1005.2841 | H35: 989.53771 | I35: 955.11202 | J35: 952.68415 | K35: 894.91436 | L35: 837.83712 | M35: 816.97795 | N35: 797.68904 | O35: 762.31111 | P35: 743.14898 | Q35: 731.3145 | R35: 681.00965 | S35: 630.46389 | T35: 586.13204 | U35: 580.34458 | V35: 567.18244 | W35: 555.55128 | X35: 548.3102 | Y35: 532.91187 | Z35: 509.89172 | AA35: 492.64296 | AB35: 491.03736 | AC35: 487.27846 | AD35: 498.6019 | AE35: 504.34831 | AF35: 503.13571 | AG35: 505.78846 | AH35: 494.15994 | AI35: 476.60845 | AJ35: 456.96223 | AK35: 454.50404 | AL35: 447.74248 | AM35: 445.24411 | AN35: 434.05908 | AO35: 425.05038 | AP35: 414.35304 | AR35: =AP35-B35 -> -693.7398 | AS35: =AR35/B35 -> -0.6260665
A36: Total Geral | B36: =SUM(B5,B12,B20,B25,B32,B35) -> 4.207828e+08 | C36: =SUM(C5,C12,C20,C25,C32,C35) -> 4.207828e+08 | D36: =SUM(D5,D12,D20,D25,D32,D35) -> 4.207828e+08 | E36: =SUM(E5,E12,E20,E25,E32,E35) -> 4.207828e+08 | F36: =SUM(F5,F12,F20,F25,F32,F35) -> 4.207828e+08 | G36: =SUM(G5,G12,G20,G25,G32,G35) -> 4.207828e+08 | H36: =SUM(H5,H12,H20,H25,H32,H35) -> 4.207828e+08 | I36: =SUM(I5,I12,I20,I25,I32,I35) -> 4.207828e+08 | ... AP36: =SUM(AP5,AP12,AP20,AP25,AP32,AP35) -> 4.207828e+08 | AR36: =AP36-B36 -> 9.5367432e-07 | AS36: =AR36/B36 -> 0
B41: 1985 | C41: 1986 | D41: 1987 | E41: 1988 | F41: 1989 | G41: 1990 | H41: 1991 | I41: 1992 | J41: 1993 | K41: 1994 | L41: 1995 | M41: 1996 | N41: 1997 | O41: 1998 | P41: 1999 | Q41: 2000 | R41: 2001 | S41: 2002 | T41: 2003 | U41: 2004 | V41: 2005 | W41: 2006 | X41: 2007 | Y41: 2008 | Z41: 2009 | AA41: 2010 | AB41: 2011 | AC41: 2012 | AD41: 2013 | AE41: 2014 | AF41: 2015 | AG41: 2016 | AH41: 2017 | AI41: 2018 | AJ41: 2019 | AK41: 2020 | AL41: 2021 | AM41: 2022 | AN41: 2023 | AO41: 2024 | AP41: 2025
A42: Floresta | B42: =B5 -> 3.8125295e+08 | C42: =C5 -> 3.8083498e+08 | D42: =D5 -> 3.793106e+08 | E42: =E5 -> 377909197 | F42: =F5 -> 3.7670774e+08 | G42: =G5 -> 375826791 | H42: =H5 -> 3.7465856e+08 | I42: =I5 -> 3.7303941e+08 | ... AP42: =AP5 -> 3.2797655e+08
A43: Pastagem | B43: =B21 -> 7746736.9 | C43: =C21 -> 9277356.7 | D43: =D21 -> 10954237 | E43: =E21 -> 12348696 | F43: =F21 -> 13466839 | G43: =G21 -> 14455453 | H43: =H21 -> 15545527 | I43: =I21 -> 17004180 | ... AP43: =AP21 -> 50828180
A44: Agricultura | B44: =B22 -> 161055.28 | C44: =C22 -> 151011.99 | D44: =D22 -> 177019.79 | E44: =E22 -> 204969.86 | F44: =F22 -> 228951.04 | G44: =G22 -> 253307.03 | H44: =H22 -> 277092.35 | I44: =I22 -> 301021.05 | ... AP44: =AP22 -> 8647890.6
A46: EM MILHOES DE HECTARES
A47: Floresta | B47: =B42/1000000 -> 381.25295 | C47: =C42/1000000 -> 380.83498 | D47: =D42/1000000 -> 379.3106 | E47: =E42/1000000 -> 377.9092 | F47: =F42/1000000 -> 376.70774 | G47: =G42/1000000 -> 375.82679 | H47: =H42/1000000 -> 374.65856 | I47: =I42/1000000 -> 373.03941 | ... AP47: =AP42/1000000 -> 327.97655
...

Sheet MANCHETES
B2: Manchetes para Amazonia
B4: ='GRAFICO HISTORICO'!AU5 -> 0.7794438 | C4: do bioma coberto por floresta natural em 2025
B5: ='GRAFICO HISTORICO'!AU6 -> 0.81452891 | C5: do bioma coberto por vegetação nativa em 2025
B6: =CONCAT(ROUND(('GRAFICO HISTORICO'!AU7/1000000),1)," Mha") -> -53,3 Mha | C6: perda de cobertura florestal líquida entre 1985 e 2025
B7: =CONCAT(ROUND(('GRAFICO HISTORICO'!AU8/1000000),1)," Mha") -> -54,7 Mha | C7: perda de vegetação nativa entre 1985 e 2025
B8: =CONCAT(ROUND(('GRAFICO HISTORICO'!AU10),2),"x") -> 4,4x | C8: expansão da agropecuária na Amazônia entre 1985 e 2025
B9: ='GRAFICO HISTORICO'!AU11 -> 0.64850313 | C9: proporção das florestas naturais do Brasil na Amazônia

Sheet Matriz Cerrado
C1: 2017
C2: Pastagem | D2: Formação Campestre (Campo) | E2: Formações Florestais | F2: Formações Savanicas | G2: Florestas Plantadas | H2: Cultivo Anual e Perene | I2: Cultivo Semi-Perene | J2: Mosaico de Cultivos | K2: Mosaico de Agricultura ou Pastagem | L2: Outros | M2: Praias e dunas | N2: Agricultura | O2: Formações Florestais Naturais | P2: Floresta | Q2: Mangue | R2: Infraestrutura Urbana | S2: Outras áreas não vegetadas | T2: Corpos Dágua | U2: Não observado | Y2: Apicum | Z2: Aquicultura | AA2: Afloramento Rochoso | AB2: Mineração | AC2: Agropecuária | AH2: Formação Natural não Florestal | AI2: Área Úmida Natural não Florestal | AJ2: Outra formação não Florestal | AK2: Área não Vegetada | AL2: Rios, Lagos e Oceanos
A3: 1985 | B3: Formações Florestais | C3: 6640658.1 | D3: 334692.75 | E3: 32748752 | F3: 5911722.5 | G3: 595157.51 | H3: 1649613.9 | I3: 131117.94 | J3: - | K3: 1037178 | L3: =SUM(M3:AL3) -> 215147.64 | M3: 1377.516 | N3: - | O3: - | P3: - | Q3: 6439.0295 | R3: 12937.489 | S3: 4.2081866 | T3: - | U3: 41.225391 | Y3: 30.271407 | Z3: - | AA3: 1841.7452 | AB3: 801.19511 | AC3: - | AH3: - | AI3: 0.93086106 | AJ3: 1.5183485 | AK3: - | AL3: 191672.51
A4: 1985 | B4: Formações Savanicas | C4: 9182233.6 | D4: 3370551.8 | E4: 3181352.5 | F4: 40719447 | G4: 386646.91 | H4: 4461769.9 | I4: 89052.774 | J4: - | K4: 1369796.9 | L4: =SUM(M4:AL4) -> 133641.05 | M4: 2172.317 | N4: - | O4: - | P4: - | Q4: 14.824048 | R4: 23307.995 | S4: 2.7310441 | T4: - | U4: 41.22684 | Y4: 41.972004 | Z4: - | AA4: 2010.8362 | AB4: 1066.1409 | AC4: - | AH4: - | AI4: - | AJ4: 1.5948859 | AK4: - | AL4: 104981.42
A5: 1985 | B5: Formação Natural não Florestal | C5: - | D5: - | E5: - | F5: - | G5: - | H5: - | I5: - | J5: - | K5: - | L5: =SUM(M5:AL5) -> 0.1784661 | M5: - | N5: - | O5: - | P5: - | Q5: - | R5: - | S5: - | T5: - | U5: - | Y5: - | Z5: - | AA5: - | AB5: - | AC5: - | AH5: 0.1784661 | AI5: - | AJ5: - | AK5: - | AL5: -
A6: 1985 | B6: Formação Campestre (Campo) | C6: 1574487.1 | D6: 17389607 | E6: 183642.82 | F6: 2489874.7 | G6: 91164.412 | H6: 1493830.3 | I6: 30597.918 | J6: - | K6: 501182.82 | L6: =SUM(M6:AL6) -> 57095.977 | M6: 2679.5681 | N6: - | O6: - | P6: - | Q6: 109.75528 | R6: 12949.911 | S6: 0.79891501 | T6: - | U6: 12.044717 | Y6: 55.015803 | Z6: - | AA6: 2870.7179 | AB6: 1214.7601 | AC6: - | AH6: - | AI6: - | AJ6: 39.439852 | AK6: - | AL6: 37163.965
A7: 1985 | B7: Florestas Plantadas | C7: 29622.562 | D7: 10957.499 | E7: 40012.079 | F7: 23430.797 | G7: 343438.98 | H7: 37236.433 | I7: 6697.3878 | J7: - | K7: 24046.344 | L7: =SUM(M7:AL7) -> 195.03893 | M7: - | N7: - | O7: - | P7: - | Q7: - | R7: 66.03449 | S7: 0.43017806 | T7: - | U7: 0.086067426 | Y7: - | Z7: - | AA7: 43.315627 | AB7: 19.233796 | AC7: - | AH7: - | AI7: - | AJ7: - | AK7: - | AL7: 65.938776
A8: 1985 | B8: Agricultura | C8: =C9+C10 -> 238074.75 | D8: =D9+D10 -> 69143.619 | E8: =E9+E10 -> 13317.227 | F8: =F9+F10 -> 8009.8403 | G8: =G9+G10 -> 16550.081 | H8: =H9+H10 -> 3719079.9 | I8: =I9+I10 -> 1128413 | J8: =J9+J10 -> #VALUE! | ... L8: =L9+L10 -> 13732.09
A9: 1985 | B9: Cultivo Anual e Perene | C9: 233791.72 | D9: 68861.861 | E9: 10079.848 | F9: 7621.5841 | G9: 14513.611 | H9: 3683857.9 | I9: 318632.89 | J9: - | K9: 100235.02 | L9: =SUM(M9:AL9) -> 7849.9927 | M9: - | N9: - | O9: - | P9: - | Q9: - | R9: 7444.3826 | S9: - | T9: - | U9: 0.34357991 | Y9: - | Z9: - | AA9: - | AB9: 1.5908749 | AC9: - | AH9: - | AI9: - | AJ9: - | AK9: - | AL9: 403.67561
A10: 1985 | B10: Cultivo Semi-Perene | C10: 4283.0335 | D10: 281.75809 | E10: 3237.379 | F10: 388.25621 | G10: 2036.4695 | H10: 35222.003 | I10: 809780.07 | J10: - | K10: 63501.195 | L10: =SUM(M10:AL10) -> 5882.0971 | M10: - | N10: - | O10: - | P10: - | Q10: - | R10: 5521.7439 | S10: - | T10: - | U10: 0.083043384 | Y10: - | Z10: - | AA10: - | AB10: 0.82992174 | AC10: - | AH10: - | AI10: - | AJ10: - | AK10: - | AL10: 359.44023
A11: 1985 | B11: Mosaico de Agricultura ou Pastagem | C11: 4896199.9 | D11: 1171056.9 | E11: 650071.8 | F11: 1930398.6 | G11: 225113.38 | H11: 3615675.7 | I11: 1103003.6 | J11: - | K11: 8609340.8 | L11: =SUM(M11:AL11) -> 96767.994 | M11: 1943.8013 | N11: - | O11: - | P11: - | Q11: 1.7862474 | R11: 56391.441 | S11: 1.6162309 | T11: - | U11: 12.733523 | Y11: 4.9105707 | Z11: - | AA11: 986.46984 | AB11: 776.13618 | AC11: - | AH11: - | AI11: - | AJ11: 0.76052543 | AK11: - | AL11: 36648.339
A12: 1985 | B12: Pastagem | C12: 24748194 | D12: 404439.38 | E12: 980917.7 | F12: 1295763 | G12: 721394.34 | H12: 4187180.2 | I12: 1618113 | J12: - | K12: 2910078.4 | L12: =SUM(M12:AL12) -> 135742.33 | M12: - | N12: - | O12: - | P12: - | Q12: - | R12: 80844.798 | S12: 1.0955579 | T12: - | U12: 10.349404 | Y12: - | Z12: - | AA12: 255.73135 | AB12: 1617.058 | AC12: - | AH12: - | AI12: - | AJ12: - | AK12: - | AL12: 53013.294
B13: Outros | C13: =SUM(C16:C37) -> 54564.298 | D13: =SUM(D16:D37) -> 41717.31 | E13: =SUM(E16:E37) -> 31572.336 | F13: =SUM(F16:F37) -> 41459.173 | G13: =SUM(G16:G37) -> 537.13227 | H13: =SUM(H16:H37) -> 7388.6339 | I13: =SUM(I16:I37) -> 209.53684 | J13: =SUM(J16:J37) -> 0 | K13: =SUM(K16:K37) -> 41053.28 | L13: =SUM(M13:AL13) -> 1589927.6 | M13: =SUM(M16:M37) -> 91576.002 | N13: =SUM(N16:N37) -> 0 | O13: =SUM(O16:O37) -> 0 | P13: =SUM(P16:P37) -> 0 | Q13: =SUM(Q16:Q37) -> 64070.851 | R13: =SUM(R16:R37) -> 304355.44 | S13: =SUM(S16:S37) -> 77.329711 | T13: =SUM(T16:T37) -> 0 | U13: =SUM(U16:U37) -> 6601.387 | Y13: =SUM(Y16:Y37) -> 1213.7038 | Z13: =SUM(Z16:Z37) -> 0 | AA13: =SUM(AA16:AA37) -> 61263.503 | AB13: =SUM(AB16:AB37) -> 1065.5543 | AC13: =SUM(AC16:AC37) -> 0 | AH13: =SUM(AH16:AH37) -> 0 | AI13: =SUM(AI16:AI37) -> 14.587313 | AJ13: =SUM(AJ16:AJ37) -> 34175.423 | AK13: =SUM(AK16:AK37) -> 0 | AL13: =SUM(AL16:AL37) -> 1025513.8
L14: =SUM(M14:AL14) -> 0
L15: =SUM(M15:AL15) -> 0
A16: 1985 | B16: Praias e dunas | C16: 306.19951 | D16: 357.54227 | E16: 41.430358 | F16: 1536.1574 | G16: - | H16: - | I16: - | J16: - | K16: 637.89746 | L16: =SUM(M16:AL16) -> 85433.105 | M16: 78805.298 | N16: - | O16: - | P16: - | Q16: 69.309059 | R16: 30.714672 | S16: - | T16: - | U16: 70.823419 | Y16: 14.200305 | Z16: - | AA16: - | AB16: - | AC16: - | AH16: - | AI16: - | AJ16: - | AK16: - | AL16: 6442.76
A17: 1985 | B17: Agricultura | C17: - | D17: - | E17: - | F17: - | G17: - | H17: - | I17: - | J17: - | K17: - | L17: =SUM(M17:AL17) -> 0 | M17: - | N17: - | O17: - | P17: - | Q17: - | R17: - | S17: - | T17: - | U17: - | Y17: - | Z17: - | AA17: - | AB17: - | AC17: - | AH17: - | AI17: - | AJ17: - | AK17: - | AL17: -
A18: 1985 | B18: Formações Florestais Naturais | C18: - | D18: - | E18: - | F18: - | G18: - | H18: - | I18: - | J18: - | K18: - | L18: =SUM(M18:AL18) -> 0 | M18: - | N18: - | O18: - | P18: - | Q18: - | R18: - | S18: - | T18: - | U18: - | Y18: - | Z18: - | AA18: - | AB18: - | AC18: - | AH18: - | AI18: - | AJ18: - | AK18: - | AL18: -
A19: 1985 | B19: Floresta | C19: - | D19: - | E19: - | F19: - | G19: - | H19: - | I19: - | J19: - | K19: - | L19: =SUM(M19:AL19) -> 0 | M19: - | N19: - | O19: - | P19: - | Q19: - | R19: - | S19: - | T19: - | U19: - | Y19: - | Z19: - | AA19: - | AB19: - | AC19: - | AH19: - | AI19: - | AJ19: - | AK19: - | AL19: -
A20: 1985 | B20: Mangue | C20: 8.3931283 | D20: 27.951086 | E20: 1245.6445 | F20: 113.41278 | G20: - | H20: - | I20: - | J20: - | K20: 0.98226638 | L20: =SUM(M20:AL20) -> 62370.168 | M20: 395.72673 | N20: - | O20: - | P20: - | Q20: 61054.763 | R20: - | S20: - | T20: - | U20: 0.80376389 | Y20: 7.9476601 | Z20: - | AA20: - | AB20: - | AC20: - | AH20: - | AI20: - | AJ20: - | AK20: - | AL20: 910.92674
A21: 1985 | B21: Infraestrutura Urbana | C21: 2727.2913 | D21: 1283.9444 | E21: 168.27293 | F21: 636.83931 | G21: 8.6294964 | H21: 364.50516 | I21: 27.691991 | J21: - | K21: 2779.5284 | L21: =SUM(M21:AL21) -> 304383.51 | M21: 4.3755711 | N21: - | O21: - | P21: - | Q21: - | R21: 304197.37 | S21: - | T21: - | U21: 0.082761182 | Y21: - | Z21: - | AA21: 1.112935 | AB21: 42.374252 | AC21: - | AH21: - | AI21: - | AJ21: - | AK21: - | AL21: 138.19065
A22: 1985 | B22: Outras áreas não vegetadas | C22: 1.9776513 | D22: 1.2106197 | E22: 6.3556593 | F22: 1.7457491 | G22: 3.4993497 | H22: 1.0285166 | I22: 1.0935747 | J22: - | K22: 10.62012 | L22: =SUM(M22:AL22) -> 75.752727 | M22: - | N22: - | O22: - | P22: - | Q22: - | R22: 0.4197945 | S22: 74.216838 | T22: - | U22: - | Y22: 0.089314642 | Z22: - | AA22: 0.16841737 | AB22: - | AC22: - | AH22: - | AI22: - | AJ22: - | AK22: - | AL22: 0.8583625
A23: 1985 | B23: Corpos Dágua | C23: - | D23: - | E23: - | F23: - | G23: - | H23: - | I23: - | J23: - | K23: - | L23: =SUM(M23:AL23) -> 0 | M23: - | N23: - | O23: - | P23: - | Q23: - | R23: - | S23: - | T23: - | U23: - | Y23: - | Z23: - | AA23: - | AB23: - | AC23: - | AH23: - | AI23: - | AJ23: - | AK23: - | AL23: -
A24: 1985 | B24: Não observado | C24: 17.135785 | D24: 6.1694494 | E24: 15.767599 | F24: 18.217092 | G24: 0.931467 | H24: 5.3424885 | I24: 0.50488153 | J24: - | K24: 8.9157261 | L24: =SUM(M24:AL24) -> 6551.0958 | M24: 13.931155 | N24: - | O24: - | P24: - | Q24: 1.6074542 | R24: 1.1661789 | S24: - | T24: - | U24: 6516.5005 | Y24: - | Z24: - | AA24: 0.59658809 | AB24: - | AC24: - | AH24: - | AI24: - | AJ24: - | AK24: - | AL24: 17.293851
L25: =SUM(M25:AL25) -> 0
L26: =SUM(M26:AL26) -> 0
L27: =SUM(M27:AL27) -> 0
A28: 1985 | B28: Apicum | C28: 0.44644481 | D28: 4.0176644 | E28: 40.181766 | F28: 2.5896733 | G28: - | H28: - | I28: - | J28: - | K28: 4.6426349 | L28: =SUM(M28:AL28) -> 1681.5108 | M28: 3.0359595 | N28: - | O28: - | P28: - | Q28: 374.69126 | R28: - | S28: 0.26783817 | T28: - | U28: - | Y28: 1035.7093 | Z28: - | AA28: - | AB28: - | AC28: - | AH28: - | AI28: - | AJ28: - | AK28: - | AL28: 267.80641
A29: 1985 | B29: Aquicultura | C29: - | D29: - | E29: - | F29: - | G29: - | H29: - | I29: - | J29: - | K29: - | L29: =SUM(M29:AL29) -> 0 | M29: - | N29: - | O29: - | P29: - | Q29: - | R29: - | S29: - | T29: - | U29: - | Y29: - | Z29: - | AA29: - | AB29: - | AC29: - | AH29: - | AI29: - | AJ29: - | AK29: - | AL29: -
A30: 1985 | B30: Afloramento Rochoso | C30: 154.58324 | D30: 2457.0917 | E30: 709.84378 | F30: 690.59415 | G30: 234.87001 | H30: 238.54976 | I30: - | J30: - | K30: 143.83244 | L30: =SUM(M30:AL30) -> 61257.65 | M30: - | N30: - | O30: - | P30: - | Q30: - | R30: 0.76644965 | S30: - | T30: - | U30: 0.17194061 | Y30: - | Z30: - | AA30: 61254.729 | AB30: 0.34051387 | AC30: - | AH30: - | AI30: - | AJ30: 0.085048389 | AK30: - | AL30: 1.5566366
A31: 1985 | B31: Mineração | C31: 59.947014 | D31: 136.61953 | E31: 159.9189 | F31: 19.494807 | G31: 9.7375924 | H31: 128.72844 | I31: 97.755948 | J31: - | K31: 280.4667 | L31: =SUM(M31:AL31) -> 1101.6805 | M31: - | N31: - | O31: - | P31: - | Q31: - | R31: 33.302368 | S31: - | T31: - | U31: - | Y31: - | Z31: - | AA31: - | AB31: 998.87881 | AC31: - | AH31: - | AI31: - | AJ31: - | AK31: - | AL31: 69.499314
A32: 1985 | B32: Agropecuária | C32: - | D32: - | E32: - | F32: - | G32: - | H32: - | I32: - | J32: - | K32: - | L32: =SUM(M32:AL32) -> 0 | M32: - | N32: - | O32: - | P32: - | Q32: - | R32: - | S32: - | T32: - | U32: - | Y32: - | Z32: - | AA32: - | AB32: - | AC32: - | AH32: - | AI32: - | AJ32: - | AK32: - | AL32: -
A33: 1985 | B33: Mosaico de Cultivos | C33: - | D33: - | E33: - | F33: - | G33: - | H33: - | I33: - | J33: - | K33: - | L33: =SUM(M33:AL33) -> 0 | M33: - | N33: - | O33: - | P33: - | Q33: - | R33: - | S33: - | T33: - | U33: - | Y33: - | Z33: - | AA33: - | AB33: - | AC33: - | AH33: - | AI33: - | AJ33: - | AK33: - | AL33: -
A34: 1985 | B34: Área Úmida Natural não Florestal | C34: 1.4326721 | D34: 5.7882294 | E34: 1.0085448 | F34: 0.42251516 | G34: - | H34: - | I34: - | J34: - | K34: - | L34: =SUM(M34:AL34) -> 14.251217 | M34: - | N34: - | O34: - | P34: - | Q34: - | R34: - | S34: - | T34: - | U34: - | Y34: - | Z34: - | AA34: - | AB34: - | AC34: - | AH34: - | AI34: 14.167244 | AJ34: - | AK34: - | AL34: 0.083972888
A35: 1985 | B35: Outra formação não Florestal | C35: 2094.9722 | D35: 17881.118 | E35: 559.48526 | F35: 15325.982 | G35: 239.00361 | H35: 5961.2433 | I35: - | J35: - | K35: 783.3093 | L35: =SUM(M35:AL35) -> 34317.912 | M35: 24.024198 | N35: - | O35: - | P35: - | Q35: - | R35: 20.712885 | S35: - | T35: - | U35: - | Y35: 0.089314966 | Z35: - | AA35: 1.2734732 | AB35: 0.2554422 | AC35: - | AH35: - | AI35: - | AJ35: 34175.249 | AK35: - | AL35: 96.307304
A36: 1985 | B36: Área não Vegetada | C36: - | D36: - | E36: - | F36: - | G36: - | H36: - | I36: - | J36: - | K36: - | L36: =SUM(M36:AL36) -> 0 | M36: - | N36: - | O36: - | P36: - | Q36: - | R36: - | S36: - | T36: - | U36: - | Y36: - | Z36: - | AA36: - | AB36: - | AC36: - | AH36: - | AI36: - | AJ36: - | AK36: - | AL36: -
A37: 1985 | B37: Rios, Lagos e Oceanos | C37: 49191.919 | D37: 19555.857 | E37: 28624.427 | F37: 23113.718 | G37: 40.460738 | H37: 689.23622 | I37: 82.490445 | J37: - | K37: 36403.085 | L37: =SUM(M37:AL37) -> 1032740.9 | M37: 12329.61 | N37: - | O37: - | P37: - | Q37: 2570.48 | R37: 70.990914 | S37: 2.8450342 | T37: - | U37: 13.004591 | Y37: 155.6679 | Z37: - | AA37: 5.6218708 | AB37: 23.70527 | AC37: - | AH37: - | AI37: 0.42006895 | AJ37: 0.089316455 | AK37: - | AL37: 1017568.5
